Workbook

Sheet 2025 Population Estimates
A1: Barangay Code | B1: Region, Province/City, Municipality and Barangay | C1: Total Pop. | D1: HH Pop | E1: Number of Households Estimates 2025 | F1: All Ages | I1: Under 1 | L1: 3-5 months | O1: 6 months | R1: 0-6 months | U1: 6-10 months | X1: 0-9 months | AA1: 6-11 months | AD1: 0-12 months | AG1: 6-17 months | AJ1: 6-23 months | AM1: 10-23 months | AP1: 11-23 months | AS1: 13-23 months | AV1: 13-24 months | AY1: 6-59 months | BB1: 9-59 months | BE1: 1-4 years | BH1: 5-9 years old | BK1: 5-11 years old | BN1: 9-14 years old | BQ1: 10-14 years old | BT1: 10-19 years old | BW1: 15-19 years old | BZ1: 20-49 years old | CC1: 0-4 years old | CF1: 0-5 years old | CI1: 0-12 years old | CL1: 5 years and above | CO1: 5-6 years old | CR1: 12-13 years old | CU1: 0-14 years old | CX1: 12-59 years old | DA1: 14-49 years old | DD1: 15-49 years old | DG1: 20-59 years old | DJ1: 20 years and above | DM1: 60-65 years old | DP1: 60 years and above
F2: Male | G2: Female | H2: Total | I2: Male | J2: Female | K2: Total | L2: Male | M2: Female | N2: Total | O2: Male | P2: Female | Q2: Total | R2: Male | S2: Female | T2: Total | U2: Male | V2: Female | W2: Total | X2: Male | Y2: Female | Z2: Total | AA2: Male | AB2: Female | AC2: Total | AD2: Male | AE2: Female | AF2: Total | AG2: Male | AH2: Female | AI2: Total | AJ2: Male | AK2: Female | AL2: Total | AM2: Male | AN2: Female | AO2: Total | AP2: Male | AQ2: Female | AR2: Total | AS2: Male | AT2: Female | AU2: Total | AV2: Male | AW2: Female | AX2: Total | AY2: Male | AZ2: Female | BA2: Total | BB2: Male | BC2: Female | BD2: Total | BE2: Male | BF2: Female | BG2: Total | BH2: Male | BI2: Female | BJ2: Total | BK2: Male | BL2: Female | BM2: Total | BN2: Male | BO2: Female | BP2: Total | BQ2: Male | BR2: Female | BS2: Total | BT2: Male | BU2: Female | BV2: Total | BW2: Male | BX2: Female | BY2: Total | BZ2: Male | CA2: Female | CB2: Total | CC2: Male | CD2: Female | CE2: Total | CF2: Male | CG2: Female | CH2: Total | CI2: Male | CJ2: Female | CK2: Total | CL2: Male | CM2: Female | CN2: Total | CO2: Male | CP2: Female | CQ2: Total | CR2: Male | CS2: Female | CT2: Total | CU2: Male | CV2: Female | CW2: Total | CX2: Male | CY2: Female | CZ2: Total | DA2: Male | DB2: Female | DC2: Total | DD2: Male | DE2: Female | DF2: Total | DG2: Male | DH2: Female | DI2: Total | DJ2: Male | DK2: Female | DL2: Total | DM2: Male | DN2: Female | DO2: Total | DP2: Male | DQ2: Female | DR2: Total
A3: 501600000 | B3: Camarines Norte | C3: 670815 | D3: 669876 | E3: 153546 | F3: 341404 | G3: 329411 | H3: 670815 | I3: 7902 | J3: 7209 | K3: 15111 | L3: 1973 | M3: 1802 | N3: 3775 | O3: 655 | P3: 603 | Q3: 1258 | R3: 4607 | S3: 4206 | T3: 8813 | U3: 3293 | V3: 2997 | W3: 6290 | X3: 6593 | Y3: 5999 | Z3: 12592 | AA3: 3951 | AB3: 3600 | AC3: 7551 | AD3: 8551 | AE3: 7821 | AF3: 16372 | AG3: 7816 | AH3: 7303 | AI3: 15119 | AJ3: 11700 | AK3: 11004 | AL3: 22704 | AM3: 9066 | AN3: 8600 | AO3: 17666 | AP3: 8404 | AQ3: 8007 | AR3: 16411 | AS3: 7100 | AT3: 6792 | AU3: 13892 | AV3: 7777 | AW3: 7425 | AX3: 15202 | AY3: 36678 | AZ3: 34178 | BA3: 70856 | BB3: 34700 | BC3: 32380 | BD3: 67080 | BE3: 32727 | BF3: 30578 | BG3: 63305 | BH3: 40752 | BI3: 37525 | BJ3: 78277 | BK3: 56690 | BL3: 52618 | BM3: 109308 | BN3: 47051 | BO3: 44036 | BP3: 91087 | BQ3: 38751 | BR3: 36493 | BS3: 75244 | BT3: 74116 | BU3: 70173 | BV3: 144289 | BW3: 35365 | BX3: 33680 | BY3: 69045 | BZ3: 132589 | CA3: 124816 | CB3: 257405 | CC3: 40629 | CD3: 37787 | CE3: 78416 | CF3: 48364 | CG3: 44772 | CH3: 93136 | CI3: 105274 | CJ3: 97902 | CK3: 203176 | CL3: 300775 | CM3: 291624 | CN3: 592399 | CO3: 15751 | CP3: 14382 | CQ3: 30133 | CR3: 15431 | CS3: 14565 | CT3: 29996 | CU3: 120132 | CV3: 111805 | CW3: 231937 | CX3: 219157 | CY3: 207254 | CZ3: 426411 | DA3: 175336 | DB3: 165331 | DC3: 340667 | DD3: 167954 | DE3: 158496 | DF3: 326450 | DG3: 160979 | DH3: 152174 | DI3: 313153 | DJ3: 185907 | DK3: 183926 | DL3: 369833 | DM3: 11991 | DN3: 12266 | DO3: 24257 | DP3: 24928 | DQ3: 31752 | DR3: 56680
A4: 501603000 | B4: Daet | C4: 118364 | D4: 117966 | E4: 26931 | F4: 58595 | G4: 59769 | H4: 118364 | I4: 1185 | J4: 1056 | K4: 2241 | L4: 297 | M4: 263 | N4: 560 | O4: 100 | P4: 87 | Q4: 187 | R4: 691 | S4: 616 | T4: 1307 | U4: 494 | V4: 439 | W4: 933 | X4: 987 | Y4: 879 | Z4: 1866 | AA4: 593 | AB4: 527 | AC4: 1120 | AD4: 1286 | AE4: 1150 | AF4: 2436 | AG4: 1199 | AH4: 1086 | AI4: 2285 | AJ4: 1804 | AK4: 1651 | AL4: 3455 | AM4: 1409 | AN4: 1299 | AO4: 2708 | AP4: 1311 | AQ4: 1211 | AR4: 2522 | AS4: 1110 | AT4: 1030 | AU4: 2140 | AV4: 1214 | AW4: 1125 | AX4: 2339 | AY4: 5580 | AZ4: 5113 | BA4: 10693 | BB4: 5284 | BC4: 4849 | BD4: 10133 | BE4: 4987 | BF4: 4586 | BG4: 9573 | BH4: 6253 | BI4: 5865 | BJ4: 12118 | BK4: 8784 | BL4: 8362 | BM4: 17146 | BN4: 7564 | BO4: 7244 | BP4: 14808 | BQ4: 6283 | BR4: 6037 | BS4: 12320 | BT4: 12659 | BU4: 12149 | BV4: 24808 | BW4: 6376 | BX4: 6112 | BY4: 12488 | BZ4: 23846 | CA4: 24345 | CB4: 48191 | CC4: 6172 | CD4: 5642 | CE4: 11814 | CF4: 7376 | CG4: 6749 | CH4: 14125 | CI4: 16188 | CJ4: 15234 | CK4: 31422 | CL4: 52423 | CM4: 54127 | CN4: 106550 | CO4: 2434 | CP4: 2210 | CQ4: 4644 | CR4: 2509 | CS4: 2381 | CT4: 4890 | CU4: 18708 | CV4: 17544 | CW4: 36252 | CX4: 39097 | CY4: 39408 | CZ4: 78505 | DA4: 31465 | DB4: 31616 | DC4: 63081 | DD4: 30222 | DE4: 30457 | DF4: 60679 | DG4: 28969 | DH4: 29756 | DI4: 58725 | DJ4: 33511 | DK4: 36113 | DL4: 69624 | DM4: 2197 | DN4: 2451 | DO4: 4648 | DP4: 4542 | DQ4: 6357 | DR4: 10899
B5: RHU I | C5: =SUM(C6:C14) -> 52568 | D5: =SUM(D6:D14) -> 52430 | E5: =SUM(E6:E14) -> 11807 | F5: =SUM(F6:F14) -> 26006 | G5: =SUM(G6:G14) -> 26562 | H5: =SUM(H6:H14) -> 52568 | I5: =SUM(I6:I14) -> 543 | J5: =SUM(J6:J14) -> 467 | ... DR5: =SUM(DR6:DR14) -> 4496
A6: 501603001 | B6: Alawihao | C6: 12494 | D6: 12427 | E6: 2723 | F6: 6213 | G6: 6281 | H6: 12494 | I6: 122 | J6: 116 | K6: 238 | L6: 31 | M6: 29 | N6: 60 | O6: 11 | P6: 9 | Q6: 20 | R6: 72 | S6: 67 | T6: 139 | U6: 51 | V6: 48 | W6: 99 | X6: 102 | Y6: 96 | Z6: 198 | AA6: 61 | AB6: 58 | AC6: 119 | AD6: 133 | AE6: 126 | AF6: 259 | AG6: 122 | AH6: 121 | AI6: 243 | AJ6: 183 | AK6: 184 | AL6: 367 | AM6: 143 | AN6: 145 | AO6: 288 | AP6: 133 | AQ6: 135 | AR6: 268 | AS6: 111 | AT6: 116 | AU6: 227 | AV6: 122 | AW6: 126 | AX6: 248 | AY6: 583 | AZ6: 583 | BA6: 1166 | BB6: 553 | BC6: 554 | BD6: 1107 | BE6: 522 | BF6: 525 | BG6: 1047 | BH6: 715 | BI6: 637 | BJ6: 1352 | BK6: 1000 | BL6: 933 | BM6: 1933 | BN6: 868 | BO6: 820 | BP6: 1688 | BQ6: 724 | BR6: 689 | BS6: 1413 | BT6: 1477 | BU6: 1409 | BV6: 2886 | BW6: 753 | BX6: 720 | BY6: 1473 | BZ6: 2494 | CA6: 2503 | CB6: 4997 | CC6: 644 | CD6: 641 | CE6: 1285 | CF6: 790 | CG6: 764 | CH6: 1554 | CI6: 1787 | CJ6: 1709 | CK6: 3496 | CL6: 5569 | CM6: 5640 | CN6: 11209 | CO6: 269 | CP6: 231 | CQ6: 500 | CR6: 286 | CS6: 263 | CT6: 549 | CU6: 2083 | CV6: 1967 | CW6: 4050 | CX6: 4199 | CY6: 4147 | CZ6: 8346 | DA6: 3400 | DB6: 3353 | DC6: 6753 | DD6: 3247 | DE6: 3223 | DF6: 6470 | DG6: 3007 | DH6: 3034 | DI6: 6041 | DJ6: 3377 | DK6: 3594 | DL6: 6971 | DM6: 183 | DN6: 223 | DO6: 406 | DP6: 370 | DQ6: 560 | DR6: 930
A7: 501603004 | B7: Bibirao | C7: 2305 | D7: 2305 | E7: 535 | F7: 1180 | G7: 1125 | H7: 2305 | I7: 22 | J7: 18 | K7: 40 | L7: 5 | M7: 5 | N7: 10 | O7: 1 | P7: 2 | Q7: 3 | R7: 12 | S7: 11 | T7: 23 | U7: 9 | V7: 8 | W7: 17 | X7: 18 | Y7: 15 | Z7: 33 | AA7: 11 | AB7: 9 | AC7: 20 | AD7: 25 | AE7: 22 | AF7: 47 | AG7: 31 | AH7: 29 | AI7: 60 | AJ7: 51 | AK7: 49 | AL7: 100 | AM7: 43 | AN7: 43 | AO7: 86 | AP7: 41 | AQ7: 42 | AR7: 83 | AS7: 37 | AT7: 36 | AU7: 73 | AV7: 41 | AW7: 37 | AX7: 78 | AY7: 151 | AZ7: 126 | BA7: 277 | BB7: 145 | BC7: 122 | BD7: 267 | BE7: 140 | BF7: 117 | BG7: 257 | BH7: 135 | BI7: 129 | BJ7: 264 | BK7: 181 | BL7: 174 | BM7: 355 | BN7: 136 | BO7: 157 | BP7: 293 | BQ7: 108 | BR7: 120 | BS7: 228 | BT7: 223 | BU7: 249 | BV7: 472 | BW7: 115 | BX7: 129 | BY7: 244 | BZ7: 471 | CA7: 439 | CB7: 910 | CC7: 162 | CD7: 135 | CE7: 297 | CF7: 191 | CG7: 153 | CH7: 344 | CI7: 363 | CJ7: 337 | CK7: 700 | CL7: 1018 | CM7: 990 | CN7: 2008 | CO7: 49 | CP7: 46 | CQ7: 95 | CR7: 39 | CS7: 60 | CT7: 99 | CU7: 405 | CV7: 384 | CW7: 789 | CX7: 759 | CY7: 740 | CZ7: 1499 | DA7: 609 | DB7: 583 | DC7: 1192 | DD7: 586 | DE7: 568 | DF7: 1154 | DG7: 582 | DH7: 536 | DI7: 1118 | DJ7: 660 | DK7: 612 | DL7: 1272 | DM7: 39 | DN7: 35 | DO7: 74 | DP7: 78 | DQ7: 76 | DR7: 154
A8: 501603006 | B8: Calasgasan | C8: 4386 | D8: 4386 | E8: 1001 | F8: 2219 | G8: 2167 | H8: 4386 | I8: 29 | J8: 35 | K8: 64 | L8: 7 | M8: 9 | N8: 16 | O8: 2 | P8: 3 | Q8: 5 | R8: 16 | S8: 21 | T8: 37 | U8: 12 | V8: 15 | W8: 27 | X8: 24 | Y8: 30 | Z8: 54 | AA8: 14 | AB8: 18 | AC8: 32 | AD8: 32 | AE8: 39 | AF8: 71 | AG8: 33 | AH8: 40 | AI8: 73 | AJ8: 53 | AK8: 61 | AL8: 114 | AM8: 43 | AN8: 49 | AO8: 92 | AP8: 41 | AQ8: 46 | AR8: 87 | AS8: 36 | AT8: 39 | AU8: 75 | AV8: 41 | AW8: 42 | AX8: 83 | AY8: 199 | AZ8: 192 | BA8: 391 | BB8: 192 | BC8: 183 | BD8: 375 | BE8: 185 | BF8: 174 | BG8: 359 | BH8: 250 | BI8: 208 | BJ8: 458 | BK8: 345 | BL8: 321 | BM8: 666 | BN8: 296 | BO8: 303 | BP8: 599 | BQ8: 242 | BR8: 256 | BS8: 498 | BT8: 491 | BU8: 479 | BV8: 970 | BW8: 249 | BX8: 223 | BY8: 472 | BZ8: 922 | CA8: 898 | CB8: 1820 | CC8: 214 | CD8: 209 | CE8: 423 | CF8: 263 | CG8: 232 | CH8: 495 | CI8: 610 | CJ8: 585 | CK8: 1195 | CL8: 2005 | CM8: 1958 | CN8: 3963 | CO8: 98 | CP8: 73 | CQ8: 171 | CR8: 97 | CS8: 101 | CT8: 198 | CU8: 706 | CV8: 673 | CW8: 1379 | CX8: 1504 | CY8: 1429 | CZ8: 2933 | DA8: 1221 | DB8: 1163 | DC8: 2384 | DD8: 1171 | DE8: 1121 | DF8: 2292 | DG8: 1108 | DH8: 1063 | DI8: 2171 | DJ8: 1264 | DK8: 1271 | DL8: 2535 | DM8: 79 | DN8: 72 | DO8: 151 | DP8: 156 | DQ8: 208 | DR8: 364
A9: 501603007 | B9: Camambugan | C9: 10067 | D9: 10049 | E9: 2216 | F9: 4933 | G9: 5134 | H9: 10067 | I9: 102 | J9: 76 | K9: 178 | L9: 26 | M9: 19 | N9: 45 | O9: 9 | P9: 6 | Q9: 15 | R9: 60 | S9: 44 | T9: 104 | U9: 43 | V9: 31 | W9: 74 | X9: 85 | Y9: 63 | Z9: 148 | AA9: 51 | AB9: 38 | AC9: 89 | AD9: 112 | AE9: 82 | AF9: 194 | AG9: 107 | AH9: 78 | AI9: 185 | AJ9: 162 | AK9: 119 | AL9: 281 | AM9: 128 | AN9: 93 | AO9: 221 | AP9: 120 | AQ9: 87 | AR9: 207 | AS9: 101 | AT9: 75 | AU9: 176 | AV9: 109 | AW9: 85 | AX9: 194 | AY9: 481 | AZ9: 439 | BA9: 920 | BB9: 456 | BC9: 420 | BD9: 876 | BE9: 430 | BF9: 401 | BG9: 831 | BH9: 485 | BI9: 480 | BJ9: 965 | BK9: 687 | BL9: 689 | BM9: 1376 | BN9: 658 | BO9: 591 | BP9: 1249 | BQ9: 559 | BR9: 496 | BS9: 1055 | BT9: 1079 | BU9: 985 | BV9: 2064 | BW9: 520 | BX9: 489 | BY9: 1009 | BZ9: 1984 | CA9: 2135 | CB9: 4119 | CC9: 532 | CD9: 477 | CE9: 1009 | CF9: 621 | CG9: 570 | CH9: 1191 | CI9: 1354 | CJ9: 1255 | CK9: 2609 | CL9: 4401 | CM9: 4657 | CN9: 9058 | CO9: 191 | CP9: 173 | CQ9: 364 | CR9: 248 | CS9: 193 | CT9: 441 | CU9: 1576 | CV9: 1453 | CW9: 3029 | CX9: 3307 | CY9: 3373 | CZ9: 6680 | DA9: 2613 | DB9: 2718 | DC9: 5331 | DD9: 2504 | DE9: 2624 | DF9: 5128 | DG9: 2430 | DH9: 2597 | DI9: 5027 | DJ9: 2837 | DK9: 3192 | DL9: 6029 | DM9: 194 | DN9: 230 | DO9: 424 | DP9: 407 | DQ9: 595 | DR9: 1002
A10: 501603012 | B10: Dogongan | C10: 4476 | D10: 4454 | E10: 1011 | F10: 2256 | G10: 2220 | H10: 4476 | I10: 62 | J10: 54 | K10: 116 | L10: 16 | M10: 13 | N10: 29 | O10: 6 | P10: 4 | Q10: 10 | R10: 37 | S10: 31 | T10: 68 | U10: 26 | V10: 22 | W10: 48 | X10: 52 | Y10: 45 | Z10: 97 | AA10: 31 | AB10: 27 | AC10: 58 | AD10: 67 | AE10: 57 | AF10: 124 | AG10: 59 | AH10: 46 | AI10: 105 | AJ10: 86 | AK10: 66 | AL10: 152 | AM10: 66 | AN10: 48 | AO10: 114 | AP10: 61 | AQ10: 43 | AR10: 104 | AS10: 50 | AT10: 36 | AU10: 86 | AV10: 55 | AW10: 41 | AX10: 96 | AY10: 246 | AZ10: 236 | BA10: 482 | BB10: 231 | BC10: 222 | BD10: 453 | BE10: 215 | BF10: 209 | BG10: 424 | BH10: 277 | BI10: 289 | BJ10: 566 | BK10: 374 | BL10: 405 | BM10: 779 | BN10: 294 | BO10: 286 | BP10: 580 | BQ10: 231 | BR10: 230 | BS10: 461 | BT10: 453 | BU10: 439 | BV10: 892 | BW10: 222 | BX10: 209 | BY10: 431 | BZ10: 965 | CA10: 900 | CB10: 1865 | CC10: 277 | CD10: 263 | CE10: 540 | CF10: 332 | CG10: 313 | CH10: 645 | CI10: 686 | CJ10: 719 | CK10: 1405 | CL10: 1979 | CM10: 1957 | CN10: 3936 | CO10: 108 | CP10: 109 | CQ10: 217 | CR10: 83 | CS10: 81 | CT10: 164 | CU10: 785 | CV10: 782 | CW10: 1567 | CX10: 1474 | CY10: 1389 | CZ10: 2863 | DA10: 1238 | DB10: 1142 | DC10: 2380 | DD10: 1187 | DE10: 1109 | DF10: 2296 | DG10: 1118 | DH10: 1066 | DI10: 2184 | DJ10: 1249 | DK10: 1229 | DL10: 2478 | DM10: 72 | DN10: 69 | DO10: 141 | DP10: 131 | DQ10: 163 | DR10: 294
A11: 501603018 | B11: Magang | C11: 8138 | D11: 8131 | E11: 1817 | F11: 4023 | G11: 4115 | H11: 8138 | I11: 106 | J11: 77 | K11: 183 | L11: 27 | M11: 19 | N11: 46 | O11: 9 | P11: 6 | Q11: 15 | R11: 62 | S11: 44 | T11: 106 | U11: 45 | V11: 32 | W11: 77 | X11: 89 | Y11: 64 | Z11: 153 | AA11: 53 | AB11: 38 | AC11: 91 | AD11: 114 | AE11: 84 | AF11: 198 | AG11: 97 | AH11: 80 | AI11: 177 | AJ11: 140 | AK11: 123 | AL11: 263 | AM11: 105 | AN11: 97 | AO11: 202 | AP11: 96 | AQ11: 91 | AR11: 187 | AS11: 79 | AT11: 78 | AU11: 157 | AV11: 86 | AW11: 85 | AX11: 171 | AY11: 418 | AZ11: 355 | BA11: 773 | BB11: 392 | BC11: 336 | BD11: 728 | BE11: 365 | BF11: 317 | BG11: 682 | BH11: 459 | BI11: 381 | BJ11: 840 | BK11: 627 | BL11: 541 | BM11: 1168 | BN11: 516 | BO11: 492 | BP11: 1008 | BQ11: 426 | BR11: 405 | BS11: 831 | BT11: 837 | BU11: 802 | BV11: 1639 | BW11: 411 | BX11: 397 | BY11: 808 | BZ11: 1613 | CA11: 1777 | CB11: 3390 | CC11: 471 | CD11: 394 | CE11: 865 | CF11: 559 | CG11: 465 | CH11: 1024 | CI11: 1181 | CJ11: 1019 | CK11: 2200 | CL11: 3552 | CM11: 3721 | CN11: 7273 | CO11: 181 | CP11: 151 | CQ11: 332 | CR11: 176 | CS11: 169 | CT11: 345 | CU11: 1356 | CV11: 1180 | CW11: 2536 | CX11: 2609 | CY11: 2782 | CZ11: 5391 | DA11: 2106 | DB11: 2250 | DC11: 4356 | DD11: 2024 | DE11: 2174 | DF11: 4198 | DG11: 1940 | DH11: 2140 | DI11: 4080 | DJ11: 2256 | DK11: 2538 | DL11: 4794 | DM11: 149 | DN11: 170 | DO11: 319 | DP11: 316 | DQ11: 398 | DR11: 714
A12: 501603021 | B12: Mancruz | C12: 3845 | D12: 3842 | E12: 915 | F12: 1869 | G12: 1976 | H12: 3845 | I12: 38 | J12: 38 | K12: 76 | L12: 10 | M12: 9 | N12: 19 | O12: 4 | P12: 3 | Q12: 7 | R12: 23 | S12: 22 | T12: 45 | U12: 16 | V12: 15 | W12: 31 | X12: 32 | Y12: 31 | Z12: 63 | AA12: 19 | AB12: 19 | AC12: 38 | AD12: 43 | AE12: 41 | AF12: 84 | AG12: 45 | AH12: 37 | AI12: 82 | AJ12: 71 | AK12: 55 | AL12: 126 | AM12: 59 | AN12: 42 | AO12: 101 | AP12: 56 | AQ12: 39 | AR12: 95 | AS12: 47 | AT12: 33 | AU12: 80 | AV12: 50 | AW12: 36 | AX12: 86 | AY12: 197 | AZ12: 175 | BA12: 372 | BB12: 188 | BC12: 165 | BD12: 353 | BE12: 178 | BF12: 156 | BG12: 334 | BH12: 198 | BI12: 177 | BJ12: 375 | BK12: 286 | BL12: 253 | BM12: 539 | BN12: 269 | BO12: 221 | BP12: 490 | BQ12: 227 | BR12: 183 | BS12: 410 | BT12: 411 | BU12: 389 | BV12: 800 | BW12: 184 | BX12: 206 | BY12: 390 | BZ12: 796 | CA12: 908 | CB12: 1704 | CC12: 216 | CD12: 194 | CE12: 410 | CF12: 249 | CG12: 232 | CH12: 481 | CI12: 534 | CJ12: 480 | CK12: 1014 | CL12: 1653 | CM12: 1782 | CN12: 3435 | CO12: 89 | CP12: 66 | CQ12: 155 | CR12: 86 | CS12: 70 | CT12: 156 | CU12: 641 | CV12: 554 | CW12: 1195 | CX12: 1264 | CY12: 1386 | CZ12: 2650 | DA12: 1033 | DB12: 1151 | DC12: 2184 | DD12: 980 | DE12: 1114 | DF12: 2094 | DG12: 941 | DH12: 1073 | DI12: 2014 | DJ12: 1044 | DK12: 1216 | DL12: 2260 | DM12: 53 | DN12: 63 | DO12: 116 | DP12: 103 | DQ12: 143 | DR12: 246
A13: 501603023 | B13: Pamorangon | C13: 3638 | D13: 3634 | E13: 823 | F13: 1800 | G13: 1838 | H13: 3638 | I13: 34 | J13: 31 | K13: 65 | L13: 8 | M13: 8 | N13: 16 | O13: 2 | P13: 3 | Q13: 5 | R13: 19 | S13: 19 | T13: 38 | U13: 14 | V13: 13 | W13: 27 | X13: 28 | Y13: 26 | Z13: 54 | AA13: 17 | AB13: 16 | AC13: 33 | AD13: 36 | AE13: 35 | AF13: 71 | AG13: 33 | AH13: 39 | AI13: 72 | AJ13: 49 | AK13: 62 | AL13: 111 | AM13: 37 | AN13: 52 | AO13: 89 | AP13: 34 | AQ13: 49 | AR13: 83 | AS13: 30 | AT13: 42 | AU13: 72 | AV13: 33 | AW13: 44 | AX13: 77 | AY13: 155 | AZ13: 148 | BA13: 303 | BB13: 146 | BC13: 140 | BD13: 286 | BE13: 138 | BF13: 132 | BG13: 270 | BH13: 182 | BI13: 179 | BJ13: 361 | BK13: 264 | BL13: 258 | BM13: 522 | BN13: 237 | BO13: 226 | BP13: 463 | BQ13: 201 | BR13: 179 | BS13: 380 | BT13: 391 | BU13: 341 | BV13: 732 | BW13: 190 | BX13: 162 | BY13: 352 | BZ13: 717 | CA13: 737 | CB13: 1454 | CC13: 172 | CD13: 163 | CE13: 335 | CF13: 215 | CG13: 187 | CH13: 402 | CI13: 474 | CJ13: 464 | CK13: 938 | CL13: 1628 | CM13: 1675 | CN13: 3303 | CO13: 76 | CP13: 60 | CQ13: 136 | CR13: 73 | CS13: 75 | CT13: 148 | CU13: 555 | CV13: 521 | CW13: 1076 | CX13: 1178 | CY13: 1177 | CZ13: 2355 | DA13: 953 | DB13: 924 | DC13: 1877 | DD13: 907 | DE13: 899 | DF13: 1806 | DG13: 869 | DH13: 915 | DI13: 1784 | DJ13: 1055 | DK13: 1155 | DL13: 2210 | DM13: 92 | DN13: 92 | DO13: 184 | DP13: 186 | DQ13: 240 | DR13: 426
A14: 501603025 | B14: Barangay II | C14: 3219 | D14: 3202 | E14: 766 | F14: 1513 | G14: 1706 | H14: 3219 | I14: 28 | J14: 22 | K14: 50 | L14: 7 | M14: 6 | N14: 13 | O14: 2 | P14: 2 | Q14: 4 | R14: 16 | S14: 13 | T14: 29 | U14: 11 | V14: 10 | W14: 21 | X14: 23 | Y14: 19 | Z14: 42 | AA14: 14 | AB14: 11 | AC14: 25 | AD14: 29 | AE14: 24 | AF14: 53 | AG14: 24 | AH14: 19 | AI14: 43 | AJ14: 35 | AK14: 27 | AL14: 62 | AM14: 25 | AN14: 20 | AO14: 45 | AP14: 23 | AQ14: 18 | AR14: 41 | AS14: 20 | AT14: 14 | AU14: 34 | AV14: 23 | AW14: 16 | AX14: 39 | AY14: 117 | AZ14: 115 | BA14: 232 | BB14: 110 | BC14: 110 | BD14: 220 | BE14: 103 | BF14: 104 | BG14: 207 | BH14: 138 | BI14: 151 | BJ14: 289 | BK14: 201 | BL14: 210 | BM14: 411 | BN14: 174 | BO14: 210 | BP14: 384 | BQ14: 152 | BR14: 168 | BS14: 320 | BT14: 323 | BU14: 347 | BV14: 670 | BW14: 171 | BX14: 179 | BY14: 350 | BZ14: 631 | CA14: 675 | CB14: 1306 | CC14: 131 | CD14: 126 | CE14: 257 | CF14: 155 | CG14: 146 | CH14: 301 | CI14: 368 | CJ14: 366 | CK14: 734 | CL14: 1382 | CM14: 1580 | CN14: 2962 | CO14: 56 | CP14: 46 | CQ14: 102 | CR14: 64 | CS14: 75 | CT14: 139 | CU14: 421 | CV14: 445 | CW14: 866 | CX14: 1051 | CY14: 1134 | CZ14: 2185 | DA14: 827 | DB14: 888 | DC14: 1715 | DD14: 802 | DE14: 854 | DF14: 1656 | DG14: 791 | DH14: 846 | DI14: 1637 | DJ14: 921 | DK14: 1082 | DL14: 2003 | DM14: 65 | DN14: 90 | DO14: 155 | DP14: 130 | DQ14: 236 | DR14: 366
B15: RHU II | C15: =SUM(C16:C24) -> 33322 | D15: =SUM(D16:D24) -> 33216 | E15: =SUM(E16:E24) -> 7651 | F15: =SUM(F16:F24) -> 16498 | G15: =SUM(G16:G24) -> 16824 | H15: =SUM(H16:H24) -> 33322 | I15: =SUM(I16:I24) -> 344 | J15: =SUM(J16:J24) -> 309 | ... DR15: =SUM(DR16:DR24) -> 3057
A16: 501603003 | B16: Bagasbas | C16: 6000 | D16: 5993 | E16: 1348 | F16: 3074 | G16: 2926 | H16: 6000 | I16: 51 | J16: 56 | K16: 107 | L16: 13 | M16: 14 | N16: 27 | O16: 5 | P16: 4 | Q16: 9 | R16: 30 | S16: 32 | T16: 62 | U16: 22 | V16: 23 | W16: 45 | X16: 43 | Y16: 46 | Z16: 89 | AA16: 26 | AB16: 28 | AC16: 54 | AD16: 57 | AE16: 58 | AF16: 115 | AG16: 61 | AH16: 45 | AI16: 106 | AJ16: 96 | AK16: 63 | AL16: 159 | AM16: 79 | AN16: 44 | AO16: 123 | AP16: 75 | AQ16: 39 | AR16: 114 | AS16: 64 | AT16: 33 | AU16: 97 | AV16: 69 | AW16: 39 | AX16: 108 | AY16: 331 | AZ16: 256 | BA16: 587 | BB16: 318 | BC16: 242 | BD16: 560 | BE16: 305 | BF16: 228 | BG16: 533 | BH16: 347 | BI16: 324 | BJ16: 671 | BK16: 495 | BL16: 457 | BM16: 952 | BN16: 398 | BO16: 390 | BP16: 788 | BQ16: 321 | BR16: 327 | BS16: 648 | BT16: 658 | BU16: 593 | BV16: 1251 | BW16: 337 | BX16: 266 | BY16: 603 | BZ16: 1198 | CA16: 1171 | CB16: 2369 | CC16: 356 | CD16: 284 | CE16: 640 | CF16: 413 | CG16: 346 | CH16: 759 | CI16: 907 | CJ16: 811 | CK16: 1718 | CL16: 2718 | CM16: 2642 | CN16: 5360 | CO16: 132 | CP16: 111 | CQ16: 243 | CR16: 112 | CS16: 142 | CT16: 254 | CU16: 1024 | CV16: 935 | CW16: 1959 | CX16: 1974 | CY16: 1902 | CZ16: 3876 | DA16: 1596 | DB16: 1489 | DC16: 3085 | DD16: 1535 | DE16: 1437 | DF16: 2972 | DG16: 1464 | DH16: 1442 | DI16: 2906 | DJ16: 1713 | DK16: 1725 | DL16: 3438 | DM16: 126 | DN16: 104 | DO16: 230 | DP16: 249 | DQ16: 283 | DR16: 532
A17: 501603008 | B17: Cobangbang | C17: 4265 | D17: 4265 | E17: 1011 | F17: 2150 | G17: 2115 | H17: 4265 | I17: 54 | J17: 32 | K17: 86 | L17: 13 | M17: 8 | N17: 21 | O17: 4 | P17: 3 | Q17: 7 | R17: 31 | S17: 19 | T17: 50 | U17: 22 | V17: 14 | W17: 36 | X17: 45 | Y17: 27 | Z17: 72 | AA17: 27 | AB17: 16 | AC17: 43 | AD17: 58 | AE17: 35 | AF17: 93 | AG17: 54 | AH17: 33 | AI17: 87 | AJ17: 81 | AK17: 50 | AL17: 131 | AM17: 63 | AN17: 40 | AO17: 103 | AP17: 58 | AQ17: 37 | AR17: 95 | AS17: 50 | AT17: 31 | AU17: 81 | AV17: 54 | AW17: 34 | AX17: 88 | AY17: 222 | AZ17: 168 | BA17: 390 | BB17: 208 | BC17: 160 | BD17: 368 | BE17: 195 | BF17: 152 | BG17: 347 | BH17: 277 | BI17: 214 | BJ17: 491 | BK17: 374 | BL17: 325 | BM17: 699 | BN17: 299 | BO17: 291 | BP17: 590 | BQ17: 251 | BR17: 252 | BS17: 503 | BT17: 479 | BU17: 483 | BV17: 962 | BW17: 228 | BX17: 231 | BY17: 459 | BZ17: 819 | CA17: 848 | CB17: 1667 | CC17: 249 | CD17: 184 | CE17: 433 | CF17: 307 | CG17: 225 | CH17: 532 | CI17: 688 | CJ17: 548 | CK17: 1236 | CL17: 1901 | CM17: 1931 | CN17: 3832 | CO17: 119 | CP17: 92 | CQ17: 211 | CR17: 100 | CS17: 86 | CT17: 186 | CU17: 777 | CV17: 650 | CW17: 1427 | CX17: 1392 | CY17: 1400 | CZ17: 2792 | DA17: 1101 | DB17: 1134 | DC17: 2235 | DD17: 1047 | DE17: 1079 | DF17: 2126 | DG17: 1010 | DH17: 1028 | DI17: 2038 | DJ17: 1145 | DK17: 1234 | DL17: 2379 | DM17: 60 | DN17: 74 | DO17: 134 | DP17: 135 | DQ17: 206 | DR17: 341
A18: 501603014 | B18: Gubat | C18: 7100 | D18: 7096 | E18: 1507 | F18: 3461 | G18: 3639 | H18: 7100 | I18: 67 | J18: 66 | K18: 133 | L18: 17 | M18: 16 | N18: 33 | O18: 6 | P18: 5 | Q18: 11 | R18: 40 | S18: 38 | T18: 78 | U18: 28 | V18: 27 | W18: 55 | X18: 56 | Y18: 55 | Z18: 111 | AA18: 34 | AB18: 33 | AC18: 67 | AD18: 72 | AE18: 72 | AF18: 144 | AG18: 64 | AH18: 71 | AI18: 135 | AJ18: 94 | AK18: 110 | AL18: 204 | AM18: 72 | AN18: 88 | AO18: 160 | AP18: 66 | AQ18: 82 | AR18: 148 | AS18: 55 | AT18: 71 | AU18: 126 | AV18: 61 | AW18: 76 | AX18: 137 | AY18: 318 | AZ18: 281 | BA18: 599 | BB18: 301 | BC18: 264 | BD18: 565 | BE18: 284 | BF18: 248 | BG18: 532 | BH18: 383 | BI18: 354 | BJ18: 737 | BK18: 521 | BL18: 503 | BM18: 1024 | BN18: 451 | BO18: 450 | BP18: 901 | BQ18: 356 | BR18: 386 | BS18: 742 | BT18: 744 | BU18: 769 | BV18: 1513 | BW18: 388 | BX18: 383 | BY18: 771 | BZ18: 1396 | CA18: 1474 | CB18: 2870 | CC18: 351 | CD18: 314 | CE18: 665 | CF18: 418 | CG18: 388 | CH18: 806 | CI18: 941 | CJ18: 922 | CK18: 1863 | CL18: 3110 | CM18: 3325 | CN18: 6435 | CO18: 135 | CP18: 140 | CQ18: 275 | CR18: 140 | CS18: 165 | CT18: 305 | CU18: 1090 | CV18: 1054 | CW18: 2144 | CX18: 2312 | CY18: 2449 | CZ18: 4761 | DA18: 1862 | DB18: 1929 | DC18: 3791 | DD18: 1784 | DE18: 1857 | DF18: 3641 | DG18: 1706 | DH18: 1829 | DI18: 3535 | DJ18: 1983 | DK18: 2202 | DL18: 4185 | DM18: 141 | DN18: 153 | DO18: 294 | DP18: 277 | DQ18: 373 | DR18: 650
A19: 501603019 | B19: Mambalite | C19: 2511 | D19: 2511 | E19: 561 | F19: 1308 | G19: 1203 | H19: 2511 | I19: 38 | J19: 20 | K19: 58 | L19: 9 | M19: 5 | N19: 14 | O19: 3 | P19: 2 | Q19: 5 | R19: 22 | S19: 12 | T19: 34 | U19: 15 | V19: 9 | W19: 24 | X19: 31 | Y19: 17 | Z19: 48 | AA19: 19 | AB19: 10 | AC19: 29 | AD19: 40 | AE19: 23 | AF19: 63 | AG19: 36 | AH19: 23 | AI19: 59 | AJ19: 53 | AK19: 36 | AL19: 89 | AM19: 40 | AN19: 30 | AO19: 70 | AP19: 37 | AQ19: 28 | AR19: 65 | AS19: 32 | AT19: 23 | AU19: 55 | AV19: 35 | AW19: 25 | AX19: 60 | AY19: 156 | AZ19: 125 | BA19: 281 | BB19: 146 | BC19: 120 | BD19: 266 | BE19: 137 | BF19: 115 | BG19: 252 | BH19: 144 | BI19: 164 | BJ19: 308 | BK19: 210 | BL19: 215 | BM19: 425 | BN19: 203 | BO19: 170 | BP19: 373 | BQ19: 175 | BR19: 134 | BS19: 309 | BT19: 330 | BU19: 253 | BV19: 583 | BW19: 155 | BX19: 119 | BY19: 274 | BZ19: 479 | CA19: 460 | CB19: 939 | CC19: 175 | CD19: 135 | CE19: 310 | CF19: 211 | CG19: 171 | CH19: 382 | CI19: 415 | CJ19: 385 | CK19: 800 | CL19: 1133 | CM19: 1068 | CN19: 2201 | CO19: 60 | CP19: 66 | CQ19: 126 | CR19: 66 | CS19: 59 | CT19: 125 | CU19: 494 | CV19: 433 | CW19: 927 | CX19: 849 | CY19: 769 | CZ19: 1618 | DA19: 677 | DB19: 603 | DC19: 1280 | DD19: 634 | DE19: 579 | DF19: 1213 | DG19: 585 | DH19: 567 | DI19: 1152 | DJ19: 659 | DK19: 651 | DL19: 1310 | DM19: 36 | DN19: 29 | DO19: 65 | DP19: 74 | DQ19: 84 | DR19: 158
A20: 501603024 | B20: Barangay I | C20: 2488 | D20: 2484 | E20: 614 | F20: 1189 | G20: 1299 | H20: 2488 | I20: 12 | J20: 23 | K20: 35 | L20: 3 | M20: 5 | N20: 8 | O20: 1 | P20: 1 | Q20: 2 | R20: 7 | S20: 13 | T20: 20 | U20: 5 | V20: 9 | W20: 14 | X20: 10 | Y20: 19 | Z20: 29 | AA20: 6 | AB20: 11 | AC20: 17 | AD20: 14 | AE20: 25 | AF20: 39 | AG20: 16 | AH20: 24 | AI20: 40 | AJ20: 26 | AK20: 37 | AL20: 63 | AM20: 22 | AN20: 29 | AO20: 51 | AP20: 21 | AQ20: 27 | AR20: 48 | AS20: 18 | AT20: 24 | AU20: 42 | AV20: 20 | AW20: 26 | AX20: 46 | AY20: 102 | AZ20: 94 | BA20: 196 | BB20: 99 | BC20: 88 | BD20: 187 | BE20: 96 | BF20: 83 | BG20: 179 | BH20: 129 | BI20: 106 | BJ20: 235 | BK20: 176 | BL20: 147 | BM20: 323 | BN20: 153 | BO20: 128 | BP20: 281 | BQ20: 122 | BR20: 106 | BS20: 228 | BT20: 249 | BU20: 230 | BV20: 479 | BW20: 127 | BX20: 124 | BY20: 251 | BZ20: 494 | CA20: 553 | CB20: 1047 | CC20: 108 | CD20: 106 | CE20: 214 | CF20: 128 | CG20: 124 | CH20: 252 | CI20: 304 | CJ20: 275 | CK20: 579 | CL20: 1081 | CM20: 1193 | CN20: 2274 | CO20: 42 | CP20: 39 | CQ20: 81 | CR20: 51 | CS20: 42 | CT20: 93 | CU20: 359 | CV20: 318 | CW20: 677 | CX20: 801 | CY20: 862 | CZ20: 1663 | DA20: 645 | DB20: 700 | DC20: 1345 | DD20: 621 | DE20: 677 | DF20: 1298 | DG20: 599 | DH20: 673 | DI20: 1272 | DJ20: 703 | DK20: 857 | DL20: 1560 | DM20: 45 | DN20: 63 | DO20: 108 | DP20: 104 | DQ20: 184 | DR20: 288
A21: 501603029 | B21: Barangay VI | C21: 2028 | D21: 2026 | E21: 497 | F21: 971 | G21: 1057 | H21: 2028 | I21: 15 | J21: 14 | K21: 29 | L21: 3 | M21: 4 | N21: 7 | O21: 1 | P21: 2 | Q21: 3 | R21: 8 | S21: 9 | T21: 17 | U21: 6 | V21: 6 | W21: 12 | X21: 12 | Y21: 12 | Z21: 24 | AA21: 7 | AB21: 7 | AC21: 14 | AD21: 16 | AE21: 16 | AF21: 32 | AG21: 17 | AH21: 17 | AI21: 34 | AJ21: 27 | AK21: 27 | AL21: 54 | AM21: 22 | AN21: 23 | AO21: 45 | AP21: 21 | AQ21: 22 | AR21: 43 | AS21: 19 | AT21: 18 | AU21: 37 | AV21: 21 | AW21: 19 | AX21: 40 | AY21: 83 | AZ21: 67 | BA21: 150 | BB21: 79 | BC21: 64 | BD21: 143 | BE21: 76 | BF21: 60 | BG21: 136 | BH21: 82 | BI21: 78 | BJ21: 160 | BK21: 111 | BL21: 115 | BM21: 226 | BN21: 99 | BO21: 108 | BP21: 207 | BQ21: 79 | BR21: 93 | BS21: 172 | BT21: 181 | BU21: 191 | BV21: 372 | BW21: 102 | BX21: 98 | BY21: 200 | BZ21: 383 | CA21: 420 | CB21: 803 | CC21: 91 | CD21: 74 | CE21: 165 | CF21: 104 | CG21: 89 | CH21: 193 | CI21: 220 | CJ21: 208 | CK21: 428 | CL21: 880 | CM21: 983 | CN21: 1863 | CO21: 27 | CP21: 29 | CQ21: 56 | CR21: 34 | CS21: 32 | CT21: 66 | CU21: 252 | CV21: 245 | CW21: 497 | CX21: 657 | CY21: 704 | CZ21: 1361 | DA21: 501 | DB21: 542 | DC21: 1043 | DD21: 485 | DE21: 518 | DF21: 1003 | DG21: 505 | DH21: 550 | DI21: 1055 | DJ21: 617 | DK21: 714 | DL21: 1331 | DM21: 61 | DN21: 56 | DO21: 117 | DP21: 112 | DQ21: 164 | DR21: 276
A22: 501603030 | B22: Barangay VII | C22: 2141 | D22: 2139 | E22: 551 | F22: 990 | G22: 1151 | H22: 2141 | I22: 21 | J22: 23 | K22: 44 | L22: 6 | M22: 5 | N22: 11 | O22: 2 | P22: 1 | Q22: 3 | R22: 13 | S22: 13 | T22: 26 | U22: 9 | V22: 9 | W22: 18 | X22: 18 | Y22: 19 | Z22: 37 | AA22: 11 | AB22: 11 | AC22: 22 | AD22: 23 | AE22: 24 | AF22: 47 | AG22: 19 | AH22: 19 | AI22: 38 | AJ22: 26 | AK22: 27 | AL22: 53 | AM22: 19 | AN22: 19 | AO22: 38 | AP22: 17 | AQ22: 17 | AR22: 34 | AS22: 13 | AT22: 15 | AU22: 28 | AV22: 14 | AW22: 17 | AX22: 31 | AY22: 76 | AZ22: 80 | BA22: 156 | BB22: 71 | BC22: 74 | BD22: 145 | BE22: 65 | BF22: 69 | BG22: 134 | BH22: 85 | BI22: 93 | BJ22: 178 | BK22: 115 | BL22: 142 | BM22: 257 | BN22: 96 | BO22: 129 | BP22: 225 | BQ22: 84 | BR22: 112 | BS22: 196 | BT22: 202 | BU22: 236 | BV22: 438 | BW22: 118 | BX22: 124 | BY22: 242 | BZ22: 438 | CA22: 480 | CB22: 918 | CC22: 86 | CD22: 92 | CE22: 178 | CF22: 108 | CG22: 109 | CH22: 217 | CI22: 218 | CJ22: 251 | CK22: 469 | CL22: 904 | CM22: 1059 | CN22: 1963 | CO22: 38 | CP22: 35 | CQ22: 73 | CR22: 42 | CS22: 35 | CT22: 77 | CU22: 255 | CV22: 297 | CW22: 552 | CX22: 701 | CY22: 767 | CZ22: 1468 | DA22: 568 | DB22: 632 | DC22: 1200 | DD22: 556 | DE22: 604 | DF22: 1160 | DG22: 529 | DH22: 580 | DI22: 1109 | DJ22: 617 | DK22: 730 | DL22: 1347 | DM22: 37 | DN22: 62 | DO22: 99 | DP22: 88 | DQ22: 150 | DR22: 238
A23: 501603031 | B23: Barangay VIII | C23: 3111 | D23: 3104 | E23: 774 | F23: 1471 | G23: 1640 | H23: 3111 | I23: 25 | J23: 18 | K23: 43 | L23: 6 | M23: 5 | N23: 11 | O23: 2 | P23: 2 | Q23: 4 | R23: 14 | S23: 11 | T23: 25 | U23: 10 | V23: 8 | W23: 18 | X23: 20 | Y23: 15 | Z23: 35 | AA23: 12 | AB23: 9 | AC23: 21 | AD23: 27 | AE23: 21 | AF23: 48 | AG23: 28 | AH23: 23 | AI23: 51 | AJ23: 44 | AK23: 37 | AL23: 81 | AM23: 36 | AN23: 31 | AO23: 67 | AP23: 34 | AQ23: 30 | AR23: 64 | AS23: 30 | AT23: 25 | AU23: 55 | AV23: 32 | AW23: 26 | AX23: 58 | AY23: 109 | AZ23: 113 | BA23: 222 | BB23: 103 | BC23: 109 | BD23: 212 | BE23: 97 | BF23: 104 | BG23: 201 | BH23: 119 | BI23: 129 | BJ23: 248 | BK23: 182 | BL23: 186 | BM23: 368 | BN23: 165 | BO23: 173 | BP23: 338 | BQ23: 146 | BR23: 152 | BS23: 298 | BT23: 318 | BU23: 333 | BV23: 651 | BW23: 172 | BX23: 181 | BY23: 353 | BZ23: 624 | CA23: 684 | CB23: 1308 | CC23: 122 | CD23: 122 | CE23: 244 | CF23: 141 | CG23: 154 | CH23: 295 | CI23: 321 | CJ23: 344 | CK23: 665 | CL23: 1349 | CM23: 1518 | CN23: 2867 | CO23: 42 | CP23: 57 | CQ23: 99 | CR23: 52 | CS23: 64 | CT23: 116 | CU23: 387 | CV23: 403 | CW23: 790 | CX23: 1037 | CY23: 1122 | CZ23: 2159 | DA23: 827 | DB23: 896 | DC23: 1723 | DD23: 796 | DE23: 865 | DF23: 1661 | DG23: 782 | DH23: 846 | DI23: 1628 | DJ23: 912 | DK23: 1056 | DL23: 1968 | DM23: 59 | DN23: 78 | DO23: 137 | DP23: 130 | DQ23: 210 | DR23: 340
A24: 501603032 | B24: San Isidro | C24: 3678 | D24: 3598 | E24: 788 | F24: 1884 | G24: 1794 | H24: 3678 | I24: 61 | J24: 57 | K24: 118 | L24: 16 | M24: 14 | N24: 30 | O24: 6 | P24: 4 | Q24: 10 | R24: 36 | S24: 33 | T24: 69 | U24: 26 | V24: 23 | W24: 49 | X24: 51 | Y24: 47 | Z24: 98 | AA24: 31 | AB24: 28 | AC24: 59 | AD24: 65 | AE24: 60 | AF24: 125 | AG24: 55 | AH24: 51 | AI24: 106 | AJ24: 79 | AK24: 75 | AL24: 154 | AM24: 59 | AN24: 56 | AO24: 115 | AP24: 54 | AQ24: 51 | AR24: 105 | AS24: 44 | AT24: 44 | AU24: 88 | AV24: 48 | AW24: 48 | AX24: 96 | AY24: 225 | AZ24: 208 | BA24: 433 | BB24: 210 | BC24: 194 | BD24: 404 | BE24: 194 | BF24: 180 | BG24: 374 | BH24: 208 | BI24: 220 | BJ24: 428 | BK24: 290 | BL24: 297 | BM24: 587 | BN24: 236 | BO24: 214 | BP24: 450 | BQ24: 200 | BR24: 178 | BS24: 378 | BT24: 393 | BU24: 378 | BV24: 771 | BW24: 193 | BX24: 200 | BY24: 393 | BZ24: 774 | CA24: 682 | CB24: 1456 | CC24: 255 | CD24: 237 | CE24: 492 | CF24: 304 | CG24: 281 | CH24: 585 | CI24: 588 | CJ24: 567 | CK24: 1155 | CL24: 1629 | CM24: 1557 | CN24: 3186 | CO24: 87 | CP24: 90 | CQ24: 177 | CR24: 79 | CS24: 68 | CT24: 147 | CU24: 663 | CV24: 635 | CW24: 1298 | CX24: 1235 | CY24: 1130 | CZ24: 2365 | DA24: 1006 | DB24: 915 | DC24: 1921 | DD24: 967 | DE24: 882 | DF24: 1849 | DG24: 924 | DH24: 829 | DI24: 1753 | DJ24: 1028 | DK24: 959 | DL24: 1987 | DM24: 48 | DN24: 66 | DO24: 114 | DP24: 104 | DQ24: 130 | DR24: 234
B25: RHU III | C25: =SUM(C26:C32) -> 32474 | D25: =SUM(D26:D32) -> 32320 | E25: =SUM(E26:E32) -> 7473 | F25: =SUM(F26:F32) -> 16091 | G25: =SUM(G26:G32) -> 16383 | H25: =SUM(H26:H32) -> 32474 | I25: =SUM(I26:I32) -> 298 | J25: =SUM(J26:J32) -> 280 | ... DR25: =SUM(DR26:DR32) -> 3346
A26: 501603026 | B26: Barangay III | C26: 1940 | D26: 1843 | E26: 485 | F26: 963 | G26: 977 | H26: 1940 | I26: 13 | J26: 14 | K26: 27 | L26: 4 | M26: 3 | N26: 7 | O26: 2 | P26: 1 | Q26: 3 | R26: 8 | S26: 8 | T26: 16 | U26: 6 | V26: 5 | W26: 11 | X26: 11 | Y26: 11 | Z26: 22 | AA26: 7 | AB26: 7 | AC26: 14 | AD26: 15 | AE26: 14 | AF26: 29 | AG26: 16 | AH26: 11 | AI26: 27 | AJ26: 24 | AK26: 15 | AL26: 39 | AM26: 20 | AN26: 10 | AO26: 30 | AP26: 19 | AQ26: 9 | AR26: 28 | AS26: 15 | AT26: 8 | AU26: 23 | AV26: 15 | AW26: 10 | AX26: 25 | AY26: 72 | AZ26: 67 | BA26: 139 | BB26: 69 | BC26: 63 | BD26: 132 | BE26: 65 | BF26: 60 | BG26: 125 | BH26: 82 | BI26: 74 | BJ26: 156 | BK26: 116 | BL26: 109 | BM26: 225 | BN26: 93 | BO26: 101 | BP26: 194 | BQ26: 74 | BR26: 79 | BS26: 153 | BT26: 175 | BU26: 178 | BV26: 353 | BW26: 101 | BX26: 99 | BY26: 200 | BZ26: 411 | CA26: 393 | CB26: 804 | CC26: 78 | CD26: 74 | CE26: 152 | CF26: 93 | CG26: 87 | CH26: 180 | CI26: 209 | CJ26: 200 | CK26: 409 | CL26: 885 | CM26: 903 | CN26: 1788 | CO26: 27 | CP26: 27 | CQ26: 54 | CR26: 30 | CS26: 30 | CT26: 60 | CU26: 234 | CV26: 227 | CW26: 461 | CX26: 645 | CY26: 640 | CZ26: 1285 | DA26: 522 | DB26: 506 | DC26: 1028 | DD26: 512 | DE26: 492 | DF26: 1004 | DG26: 504 | DH26: 497 | DI26: 1001 | DJ26: 628 | DK26: 651 | DL26: 1279 | DM26: 52 | DN26: 55 | DO26: 107 | DP26: 124 | DQ26: 154 | DR26: 278
A27: 501603027 | B27: Barangay IV | C27: 8621 | D27: 8590 | E27: 1901 | F27: 4313 | G27: 4308 | H27: 8621 | I27: 77 | J27: 62 | K27: 139 | L27: 19 | M27: 16 | N27: 35 | O27: 6 | P27: 6 | Q27: 12 | R27: 44 | S27: 37 | T27: 81 | U27: 32 | V27: 26 | W27: 58 | X27: 64 | Y27: 52 | Z27: 116 | AA27: 38 | AB27: 31 | AC27: 69 | AD27: 84 | AE27: 68 | AF27: 152 | AG27: 81 | AH27: 64 | AI27: 145 | AJ27: 124 | AK27: 97 | AL27: 221 | AM27: 98 | AN27: 77 | AO27: 175 | AP27: 92 | AQ27: 72 | AR27: 164 | AS27: 79 | AT27: 60 | AU27: 139 | AV27: 87 | AW27: 66 | AX27: 153 | AY27: 411 | AZ27: 350 | BA27: 761 | BB27: 392 | BC27: 335 | BD27: 727 | BE27: 373 | BF27: 319 | BG27: 692 | BH27: 449 | BI27: 430 | BJ27: 879 | BK27: 635 | BL27: 610 | BM27: 1245 | BN27: 576 | BO27: 528 | BP27: 1104 | BQ27: 465 | BR27: 447 | BS27: 912 | BT27: 939 | BU27: 909 | BV27: 1848 | BW27: 474 | BX27: 462 | BY27: 936 | BZ27: 1807 | CA27: 1685 | CB27: 3492 | CC27: 450 | CD27: 381 | CE27: 831 | CF27: 533 | CG27: 466 | CH27: 999 | CI27: 1181 | CJ27: 1082 | CK27: 2263 | CL27: 3863 | CM27: 3927 | CN27: 7790 | CO27: 158 | CP27: 167 | CQ27: 325 | CR27: 190 | CS27: 166 | CT27: 356 | CU27: 1364 | CV27: 1258 | CW27: 2622 | CX27: 2916 | CY27: 2816 | CZ27: 5732 | DA27: 2370 | DB27: 2248 | DC27: 4618 | DD27: 2281 | DE27: 2147 | DF27: 4428 | DG27: 2163 | DH27: 2087 | DI27: 4250 | DJ27: 2475 | DK27: 2588 | DL27: 5063 | DM27: 154 | DN27: 184 | DO27: 338 | DP27: 312 | DQ27: 501 | DR27: 813
A28: 501603028 | B28: Barangay V | C28: 5118 | D28: 5113 | E28: 1197 | F28: 2520 | G28: 2598 | H28: 5118 | I28: 47 | J28: 51 | K28: 98 | L28: 12 | M28: 12 | N28: 24 | O28: 4 | P28: 4 | Q28: 8 | R28: 28 | S28: 29 | T28: 57 | U28: 20 | V28: 21 | W28: 41 | X28: 40 | Y28: 42 | Z28: 82 | AA28: 24 | AB28: 25 | AC28: 49 | AD28: 51 | AE28: 55 | AF28: 106 | AG28: 47 | AH28: 50 | AI28: 97 | AJ28: 70 | AK28: 76 | AL28: 146 | AM28: 54 | AN28: 59 | AO28: 113 | AP28: 50 | AQ28: 55 | AR28: 105 | AS28: 42 | AT28: 47 | AU28: 89 | AV28: 45 | AW28: 52 | AX28: 97 | AY28: 207 | AZ28: 214 | BA28: 421 | BB28: 195 | BC28: 201 | BD28: 396 | BE28: 183 | BF28: 189 | BG28: 372 | BH28: 243 | BI28: 228 | BJ28: 471 | BK28: 340 | BL28: 325 | BM28: 665 | BN28: 303 | BO28: 271 | BP28: 574 | BQ28: 260 | BR28: 222 | BS28: 482 | BT28: 527 | BU28: 480 | BV28: 1007 | BW28: 267 | BX28: 258 | BY28: 525 | BZ28: 1049 | CA28: 1061 | CB28: 2110 | CC28: 230 | CD28: 240 | CE28: 470 | CF28: 272 | CG28: 283 | CH28: 555 | CI28: 620 | CJ28: 603 | CK28: 1223 | CL28: 2290 | CM28: 2358 | CN28: 4648 | CO28: 90 | CP28: 79 | CQ28: 169 | CR28: 121 | CS28: 80 | CT28: 201 | CU28: 733 | CV28: 690 | CW28: 1423 | CX28: 1715 | CY28: 1709 | CZ28: 3424 | DA28: 1358 | DB28: 1364 | DC28: 2722 | DD28: 1316 | DE28: 1319 | DF28: 2635 | DG28: 1285 | DH28: 1326 | DI28: 2611 | DJ28: 1520 | DK28: 1650 | DL28: 3170 | DM28: 116 | DN28: 116 | DO28: 232 | DP28: 235 | DQ28: 324 | DR28: 559
A29: 501603002 | B29: Awitan | C29: 1810 | D29: 1810 | E29: 437 | F29: 872 | G29: 938 | H29: 1810 | I29: 22 | J29: 30 | K29: 52 | L29: 5 | M29: 8 | N29: 13 | O29: 1 | P29: 3 | Q29: 4 | R29: 12 | S29: 18 | T29: 30 | U29: 9 | V29: 13 | W29: 22 | X29: 18 | Y29: 25 | Z29: 43 | AA29: 11 | AB29: 15 | AC29: 26 | AD29: 23 | AE29: 33 | AF29: 56 | AG29: 18 | AH29: 28 | AI29: 46 | AJ29: 26 | AK29: 41 | AL29: 67 | AM29: 18 | AN29: 31 | AO29: 49 | AP29: 16 | AQ29: 29 | AR29: 45 | AS29: 14 | AT29: 23 | AU29: 37 | AV29: 16 | AW29: 23 | AX29: 39 | AY29: 77 | AZ29: 79 | BA29: 156 | BB29: 71 | BC29: 72 | BD29: 143 | BE29: 66 | BF29: 64 | BG29: 130 | BH29: 102 | BI29: 111 | BJ29: 213 | BK29: 145 | BL29: 153 | BM29: 298 | BN29: 125 | BO29: 114 | BP29: 239 | BQ29: 103 | BR29: 94 | BS29: 197 | BT29: 186 | BU29: 185 | BV29: 371 | BW29: 83 | BX29: 91 | BY29: 174 | BZ29: 344 | CA29: 372 | CB29: 716 | CC29: 88 | CD29: 94 | CE29: 182 | CF29: 105 | CG29: 125 | CH29: 230 | CI29: 255 | CJ29: 263 | CK29: 518 | CL29: 784 | CM29: 844 | CN29: 1628 | CO29: 39 | CP29: 46 | CQ29: 85 | CR29: 43 | CS29: 32 | CT29: 75 | CU29: 293 | CV29: 299 | CW29: 592 | CX29: 573 | CY29: 600 | CZ29: 1173 | DA29: 444 | DB29: 483 | DC29: 927 | DD29: 427 | DE29: 463 | DF29: 890 | DG29: 430 | DH29: 457 | DI29: 887 | DJ29: 496 | DK29: 548 | DL29: 1044 | DM29: 27 | DN29: 34 | DO29: 61 | DP29: 66 | DQ29: 91 | DR29: 157
A30: 501603005 | B30: Borabod | C30: 4499 | D30: 4486 | E30: 1025 | F30: 2308 | G30: 2191 | H30: 4499 | I30: 58 | J30: 50 | K30: 108 | L30: 15 | M30: 12 | N30: 27 | O30: 5 | P30: 4 | Q30: 9 | R30: 34 | S30: 29 | T30: 63 | U30: 25 | V30: 20 | W30: 45 | X30: 49 | Y30: 41 | Z30: 90 | AA30: 29 | AB30: 25 | AC30: 54 | AD30: 63 | AE30: 54 | AF30: 117 | AG30: 54 | AH30: 54 | AI30: 108 | AJ30: 79 | AK30: 84 | AL30: 163 | AM30: 60 | AN30: 67 | AO30: 127 | AP30: 55 | AQ30: 63 | AR30: 118 | AS30: 45 | AT30: 55 | AU30: 100 | AV30: 49 | AW30: 59 | AX30: 108 | AY30: 235 | AZ30: 196 | BA30: 431 | BB30: 221 | BC30: 183 | BD30: 404 | BE30: 206 | BF30: 171 | BG30: 377 | BH30: 232 | BI30: 219 | BJ30: 451 | BK30: 332 | BL30: 286 | BM30: 618 | BN30: 281 | BO30: 229 | BP30: 510 | BQ30: 242 | BR30: 189 | BS30: 431 | BT30: 500 | BU30: 410 | BV30: 910 | BW30: 258 | BX30: 221 | BY30: 479 | BZ30: 902 | CA30: 868 | CB30: 1770 | CC30: 264 | CD30: 221 | CE30: 485 | CF30: 316 | CG30: 252 | CH30: 568 | CI30: 648 | CJ30: 547 | CK30: 1195 | CL30: 2044 | CM30: 1970 | CN30: 4014 | CO30: 110 | CP30: 80 | CQ30: 190 | CR30: 100 | CS30: 82 | CT30: 182 | CU30: 738 | CV30: 629 | CW30: 1367 | CX30: 1500 | CY30: 1404 | CZ30: 2904 | DA30: 1202 | DB30: 1129 | DC30: 2331 | DD30: 1160 | DE30: 1089 | DF30: 2249 | DG30: 1100 | DH30: 1061 | DI30: 2161 | DJ30: 1312 | DK30: 1341 | DL30: 2653 | DM30: 102 | DN30: 106 | DO30: 208 | DP30: 212 | DQ30: 280 | DR30: 492
A31: 501603013 | B31: Gahonon | C31: 3850 | D31: 3843 | E31: 881 | F31: 1887 | G31: 1963 | H31: 3850 | I31: 31 | J31: 29 | K31: 60 | L31: 7 | M31: 8 | N31: 15 | O31: 2 | P31: 3 | Q31: 5 | R31: 18 | S31: 17 | T31: 35 | U31: 12 | V31: 13 | W31: 25 | X31: 25 | Y31: 25 | Z31: 50 | AA31: 15 | AB31: 15 | AC31: 30 | AD31: 33 | AE31: 33 | AF31: 66 | AG31: 31 | AH31: 35 | AI31: 66 | AJ31: 48 | AK31: 54 | AL31: 102 | AM31: 38 | AN31: 44 | AO31: 82 | AP31: 35 | AQ31: 42 | AR31: 77 | AS31: 31 | AT31: 35 | AU31: 66 | AV31: 34 | AW31: 39 | AX31: 73 | AY31: 151 | AZ31: 184 | BA31: 335 | BB31: 143 | BC31: 177 | BD31: 320 | BE31: 136 | BF31: 169 | BG31: 305 | BH31: 218 | BI31: 199 | BJ31: 417 | BK31: 316 | BL31: 273 | BM31: 589 | BN31: 234 | BO31: 247 | BP31: 481 | BQ31: 197 | BR31: 197 | BS31: 394 | BT31: 386 | BU31: 377 | BV31: 763 | BW31: 189 | BX31: 180 | BY31: 369 | BZ31: 777 | CA31: 808 | CB31: 1585 | CC31: 167 | CD31: 198 | CE31: 365 | CF31: 211 | CG31: 232 | CH31: 443 | CI31: 513 | CJ31: 518 | CK31: 1031 | CL31: 1720 | CM31: 1765 | CN31: 3485 | CO31: 90 | CP31: 67 | CQ31: 157 | CR31: 65 | CS31: 87 | CT31: 152 | CU31: 582 | CV31: 594 | CW31: 1176 | CX31: 1214 | CY31: 1254 | CZ31: 2468 | DA31: 1000 | DB31: 1024 | DC31: 2024 | DD31: 966 | DE31: 988 | DF31: 1954 | DG31: 926 | DH31: 951 | DI31: 1877 | DJ31: 1116 | DK31: 1189 | DL31: 2305 | DM31: 79 | DN31: 82 | DO31: 161 | DP31: 190 | DQ31: 238 | DR31: 428
A32: 501603015 | B32: Lag-On | C32: 6636 | D32: 6635 | E32: 1547 | F32: 3228 | G32: 3408 | H32: 6636 | I32: 50 | J32: 44 | K32: 94 | L32: 12 | M32: 11 | N32: 23 | O32: 4 | P32: 4 | Q32: 8 | R32: 29 | S32: 26 | T32: 55 | U32: 20 | V32: 19 | W32: 39 | X32: 41 | Y32: 37 | Z32: 78 | AA32: 25 | AB32: 22 | AC32: 47 | AD32: 54 | AE32: 49 | AF32: 103 | AG32: 51 | AH32: 49 | AI32: 100 | AJ32: 77 | AK32: 76 | AL32: 153 | AM32: 60 | AN32: 62 | AO32: 122 | AP32: 56 | AQ32: 58 | AR32: 114 | AS32: 48 | AT32: 49 | AU32: 97 | AV32: 54 | AW32: 54 | AX32: 108 | AY32: 258 | AZ32: 262 | BA32: 520 | BB32: 245 | BC32: 251 | BD32: 496 | BE32: 233 | BF32: 240 | BG32: 473 | BH32: 314 | BI32: 291 | BJ32: 605 | BK32: 461 | BL32: 435 | BM32: 896 | BN32: 404 | BO32: 395 | BP32: 799 | BQ32: 338 | BR32: 343 | BS32: 681 | BT32: 707 | BU32: 704 | BV32: 1411 | BW32: 369 | BX32: 361 | BY32: 730 | BZ32: 1358 | CA32: 1414 | CB32: 2772 | CC32: 283 | CD32: 284 | CE32: 567 | CF32: 337 | CG32: 355 | CH32: 692 | CI32: 803 | CJ32: 776 | CK32: 1579 | CL32: 2945 | CM32: 3124 | CN32: 6069 | CO32: 121 | CP32: 130 | CQ32: 251 | CR32: 132 | CS32: 124 | CT32: 256 | CU32: 935 | CV32: 918 | CW32: 1853 | CX32: 2231 | CY32: 2323 | CZ32: 4554 | DA32: 1786 | DB32: 1850 | DC32: 3636 | DD32: 1727 | DE32: 1775 | DF32: 3502 | DG32: 1671 | DH32: 1763 | DI32: 3434 | DJ32: 1924 | DK32: 2129 | DL32: 4053 | DM32: 128 | DN32: 145 | DO32: 273 | DP32: 253 | DQ32: 366 | DR32: 619

Sheet M2_8PAA_Pamorangon
D1: FHSIS REPORT for the Month | H1: OCTOBER | K1: Year | L1: 2025 | U1: M2
D2: Name of Health Facility | H2: PAMORANGON BARANGAY HEALTH STATION
D3: Name of Barangay | H3: PAMORANGON
D4: Name of Municipality/City | H4: DAET
D5: Name of Province | H5: CAMARINES NORTE
D6: Projected Population of the Year | H6: 3638
D7: For submission to the next administrative level
A8: SECTION A. CHILD CARE AND SERVICES
A9: Indicators | B9: Sex | E9: Remarks | L9: Indicators | Q9: Sex | T9: Remarks
B10: Male | C10: Female | D10: Total | Q10: Male | R10: Female | S10: Total
A11: IMMUNIZATION
A12: A.1. Immunization Services
A13: 1. Children protected at birth (CPAB) | B13: ='ST_Child, OHC, NCD, & Infectiou'!C9 -> 22 | C13: ='ST_Child, OHC, NCD, & Infectiou'!D9 -> 20 | D13: =SUM(B13:C13) -> 42 | L13: 4. Hep B antigen within 24 hrs after birth | Q13: ='ST_Child, OHC, NCD, & Infectiou'!C12 -> 15 | R13: ='ST_Child, OHC, NCD, & Infectiou'!D12 -> 15 | S13: =SUM(Q13:R13) -> 30
A14: 2. BCG (within 0-28 days) | B14: ='ST_Child, OHC, NCD, & Infectiou'!C10 -> 15 | C14: ='ST_Child, OHC, NCD, & Infectiou'!D10 -> 16 | D14: =SUM(B14:C14) -> 31 | L14: 5. Hep B antigen more than 24 hrs up to 14 days | Q14: ='ST_Child, OHC, NCD, & Infectiou'!C13 -> 14 | R14: ='ST_Child, OHC, NCD, & Infectiou'!D13 -> 6 | S14: =SUM(Q14:R14) -> 20
A15: 3. BCG (29 days to 1 year old) | B15: ='ST_Child, OHC, NCD, & Infectiou'!C11 -> 0 | C15: ='ST_Child, OHC, NCD, & Infectiou'!D11 -> 0 | D15: =SUM(B15:C15) -> 0
A16: A.2. Immunization Services (0-12 months old)
A17: 1. DPT-HiB-HepB 1 | B17: ='ST_Child, OHC, NCD, & Infectiou'!C15 -> 30 | C17: ='ST_Child, OHC, NCD, & Infectiou'!D15 -> 21 | D17: =SUM(B17:C17) -> 51 | L17: 8. IPV 2 | Q17: ='ST_Child, OHC, NCD, & Infectiou'!C22 -> 24 | R17: ='ST_Child, OHC, NCD, & Infectiou'!D22 -> 12 | S17: =SUM(Q17:R17) -> 36
A18: 2. DPT-HiB-HepB 2 | B18: ='ST_Child, OHC, NCD, & Infectiou'!C16 -> 31 | C18: ='ST_Child, OHC, NCD, & Infectiou'!D16 -> 18 | D18: =SUM(B18:C18) -> 49 | L18: 9. PCV 1 | Q18: ='ST_Child, OHC, NCD, & Infectiou'!C23 -> 30 | R18: ='ST_Child, OHC, NCD, & Infectiou'!D23 -> 22 | S18: =SUM(Q18:R18) -> 52
A19: 3. DPT-HiB-HepB 3 | B19: ='ST_Child, OHC, NCD, & Infectiou'!C17 -> 29 | C19: ='ST_Child, OHC, NCD, & Infectiou'!D17 -> 22 | D19: =SUM(B19:C19) -> 51 | L19: 10. PCV 2 | Q19: ='ST_Child, OHC, NCD, & Infectiou'!C24 -> 33 | R19: ='ST_Child, OHC, NCD, & Infectiou'!D24 -> 18 | S19: =SUM(Q19:R19) -> 51
A20: 4. OPV 1 | B20: ='ST_Child, OHC, NCD, & Infectiou'!C18 -> 7 | C20: ='ST_Child, OHC, NCD, & Infectiou'!D18 -> 2 | D20: =SUM(B20:C20) -> 9 | L20: 11. PCV 3 | Q20: ='ST_Child, OHC, NCD, & Infectiou'!C25 -> 35 | R20: ='ST_Child, OHC, NCD, & Infectiou'!D25 -> 18 | S20: =SUM(Q20:R20) -> 53
A21: 5. OPV 2 | B21: ='ST_Child, OHC, NCD, & Infectiou'!C19 -> 6 | C21: ='ST_Child, OHC, NCD, & Infectiou'!D19 -> 2 | D21: =SUM(B21:C21) -> 8 | L21: 12. MMR 1 | Q21: ='ST_Child, OHC, NCD, & Infectiou'!C26 -> 26 | R21: ='ST_Child, OHC, NCD, & Infectiou'!D26 -> 11 | S21: =SUM(Q21:R21) -> 37
A22: 6. OPV 3 | B22: ='ST_Child, OHC, NCD, & Infectiou'!C20 -> 4 | C22: ='ST_Child, OHC, NCD, & Infectiou'!D20 -> 2 | D22: =SUM(B22:C22) -> 6 | L22: 13. MMR 2 | Q22: ='ST_Child, OHC, NCD, & Infectiou'!C27 -> 26 | R22: ='ST_Child, OHC, NCD, & Infectiou'!D27 -> 13 | S22: =SUM(Q22:R22) -> 39
A23: 7. IPV 1 | B23: ='ST_Child, OHC, NCD, & Infectiou'!C21 -> 29 | C23: ='ST_Child, OHC, NCD, & Infectiou'!D21 -> 16 | D23: =SUM(B23:C23) -> 45 | L23: 14. FIC | Q23: ='ST_Child, OHC, NCD, & Infectiou'!C28 -> 26 | R23: ='ST_Child, OHC, NCD, & Infectiou'!D28 -> 11 | S23: =SUM(Q23:R23) -> 37
A24: A.3. Immunization Services (13-23 months old)
A25: 1. DPT-HiB-HepB 1 | B25: ='ST_Child, OHC, NCD, & Infectiou'!C30 -> 0 | C25: ='ST_Child, OHC, NCD, & Infectiou'!D30 -> 1 | D25: =SUM(B25:C25) -> 1 | L25: 8. IPV 2 | Q25: ='ST_Child, OHC, NCD, & Infectiou'!C37 -> 0 | R25: ='ST_Child, OHC, NCD, & Infectiou'!D37 -> 0 | S25: =SUM(Q25:R25) -> 0
A26: 2. DPT-HiB-HepB 2 | B26: ='ST_Child, OHC, NCD, & Infectiou'!C31 -> 0 | C26: ='ST_Child, OHC, NCD, & Infectiou'!D31 -> 0 | D26: =SUM(B26:C26) -> 0 | L26: 9. PCV 1 | Q26: ='ST_Child, OHC, NCD, & Infectiou'!C38 -> 0 | R26: ='ST_Child, OHC, NCD, & Infectiou'!D38 -> 1 | S26: =SUM(Q26:R26) -> 1
A27: 3. DPT-HiB-HepB 3 | B27: ='ST_Child, OHC, NCD, & Infectiou'!C32 -> 0 | C27: ='ST_Child, OHC, NCD, & Infectiou'!D32 -> 0 | D27: =SUM(B27:C27) -> 0 | L27: 10. PCV 2 | Q27: ='ST_Child, OHC, NCD, & Infectiou'!C39 -> 0 | R27: ='ST_Child, OHC, NCD, & Infectiou'!D39 -> 0 | S27: =SUM(Q27:R27) -> 0
A28: 4. OPV 1 | B28: ='ST_Child, OHC, NCD, & Infectiou'!C33 -> 0 | C28: ='ST_Child, OHC, NCD, & Infectiou'!D33 -> 0 | D28: =SUM(B28:C28) -> 0 | L28: 11. PCV 3 | Q28: ='ST_Child, OHC, NCD, & Infectiou'!C40 -> 0 | R28: ='ST_Child, OHC, NCD, & Infectiou'!D40 -> 0 | S28: =SUM(Q28:R28) -> 0
A29: 5. OPV 2 | B29: ='ST_Child, OHC, NCD, & Infectiou'!C34 -> 0 | C29: ='ST_Child, OHC, NCD, & Infectiou'!D34 -> 0 | D29: =SUM(B29:C29) -> 0 | L29: 12. MMR 1 | Q29: ='ST_Child, OHC, NCD, & Infectiou'!C41 -> 0 | R29: ='ST_Child, OHC, NCD, & Infectiou'!D41 -> 0 | S29: =SUM(Q29:R29) -> 0
A30: 6. OPV 3 | B30: ='ST_Child, OHC, NCD, & Infectiou'!C35 -> 0 | C30: ='ST_Child, OHC, NCD, & Infectiou'!D35 -> 0 | D30: =SUM(B30:C30) -> 0 | L30: 13. MMR 2 | Q30: ='ST_Child, OHC, NCD, & Infectiou'!C42 -> 2 | R30: ='ST_Child, OHC, NCD, & Infectiou'!D42 -> 1 | S30: =SUM(Q30:R30) -> 3
A31: 7. IPV 1 | B31: ='ST_Child, OHC, NCD, & Infectiou'!C36 -> 0 | C31: ='ST_Child, OHC, NCD, & Infectiou'!D36 -> 0 | D31: =SUM(B31:C31) -> 0 | L31: 14. CIC | Q31: ='ST_Child, OHC, NCD, & Infectiou'!C43 -> 2 | R31: ='ST_Child, OHC, NCD, & Infectiou'!D43 -> 1 | S31: =SUM(Q31:R31) -> 3
A32: A.4. School-Based Immunization
A33: 1. HPV 1st dose (9 years old Female only) | C33: ='ST_Child, OHC, NCD, & Infectiou'!E45 -> 20 | D33: =SUM(B33:C33) -> 20 | L33: 4. Grade 1 learners given MR | Q33: ='ST_Child, OHC, NCD, & Infectiou'!C48 -> 22 | R33: ='ST_Child, OHC, NCD, & Infectiou'!D48 -> 30 | S33: =SUM(Q33:R33) -> 52
A34: 2. HPV 2nd dose (9 years old Female only) | C34: ='ST_Child, OHC, NCD, & Infectiou'!E46 -> 0 | D34: =SUM(B34:C34) -> 0 | L34: 5. Grade 7 learners given Td | Q34: ='ST_Child, OHC, NCD, & Infectiou'!C49 -> 0 | R34: ='ST_Child, OHC, NCD, & Infectiou'!D49 -> 0 | S34: =SUM(Q34:R34) -> 0
A35: 3. Grade 1 learners given Td | B35: ='ST_Child, OHC, NCD, & Infectiou'!C47 -> 22 | C35: ='ST_Child, OHC, NCD, & Infectiou'!D47 -> 30 | D35: =SUM(B35:C35) -> 52 | L35: 6. Grade 7 learners given MR | Q35: ='ST_Child, OHC, NCD, & Infectiou'!C50 -> 0 | R35: ='ST_Child, OHC, NCD, & Infectiou'!D50 -> 0 | S35: =SUM(Q35:R35) -> 0
A36: SECTION B. NON-COMMUNICABLE DISEASES
A37: Indicators | B37: Sex | D37: Total | E37: Remarks | L37: Indicators | P37: Sex | R37: Total | S37: Remarks
B38: Male | C38: Female | P38: Male | Q38: Female
A39: B1. Lifestyle Related
A40: 1. Adults 20-59 years old who were risk assessed using the PhilPEN protocol | B40: ='ST_Child, OHC, NCD, & Infectiou'!C142 -> 466 | C40: ='ST_Child, OHC, NCD, & Infectiou'!D142 -> 652 | D40: =SUM(B40:C40) -> 1118 | L40: 2. Senior Citizens 60 years old and above who were risk assessed using the PhilPEN protocol | P40: ='ST_Child, OHC, NCD, & Infectiou'!C149 -> 193 | Q40: ='ST_Child, OHC, NCD, & Infectiou'!D149 -> 336 | R40: =SUM(P40:Q40) -> 529
...

Sheet M1_All Programs_Pamorangon
D1: FHSIS REPORT for the Month | H1: ANNUAL | K1: Year | L1: 2025 | U1: M1 BRGY
D2: Name of Health Facility | H2: PAMORANGON BARANGAY HEALTH STATION
D3: Name of Barangay | H3: PAMORANGON
D4: Name of Municipality/City | H4: DAET
D5: Name of Province | H5: CAMARINES NORTE
D6: Projected Population of the Year | H6: 3638
A8: SECTION A. FAMILY PLANNING SERVICES FOR WOMEN OF REPRODUCTIVE AGE
A9: Demand Satisfied | E9: Age Group | Q9: Total WRA 15-49 yrs old | U9: Remarks
E10: 10-14 yrs old | I10: 15-19 yrs old | M10: 20-49 yrs old
A11: 1. No. of women of reproductive age (WRA) 15-49 years old who have demand for Family Planning (FP) and currently using, or whose partner is currently using, any modern FP methods | E11: ='ST_FP, Maternal, Morta, & Nata_'!C7 -> 0 | I11: ='ST_FP, Maternal, Morta, & Nata_'!D7 -> 4 | M11: ='ST_FP, Maternal, Morta, & Nata_'!E7 -> 158 | Q11: 899
A12: Modern FP Methods | B12: Current Users (Beginning of the Month) | F12: Acceptors | N12: Drop-outs (Present Month) | R12: Current User (End of the Month) | V12: New Acceptors (Present Month)
F13: New Acceptors (Previous Month) | J13: Other Acceptors (Present Month)
B14: Age Group | E14: TOTAL | F14: Age Group | I14: TOTAL | J14: Age Group | M14: TOTAL | N14: Age Group | Q14: TOTAL | R14: Age Group | U14: TOTAL | V14: Age Group | Y14: TOTAL
B15: 10-14 | C15: 15-19 | D15: 20-49 | F15: 10-14 | G15: 15-19 | H15: 20-49 | J15: 10-14 | K15: 15-19 | L15: 20-49 | N15: 10-14 | O15: 15-19 | P15: 20-49 | R15: 10-14 | S15: 15-19 | T15: 20-49 | V15: 10-14 | W15: 15-19 | X15: 20-49
A16: 1. BTL | B16: ='ST_FP, Maternal, Morta, & Nata_'!C9 -> 0 | C16: ='ST_FP, Maternal, Morta, & Nata_'!D9 -> 0 | D16: ='ST_FP, Maternal, Morta, & Nata_'!E9 -> 6 | E16: ='ST_FP, Maternal, Morta, & Nata_'!F9 -> 6 | F16: ='ST_FP, Maternal, Morta, & Nata_'!C28 -> 0 | G16: ='ST_FP, Maternal, Morta, & Nata_'!D28 -> 0 | H16: ='ST_FP, Maternal, Morta, & Nata_'!E28 -> 0 | I16: ='ST_FP, Maternal, Morta, & Nata_'!F28 -> 0 | J16: ='ST_FP, Maternal, Morta, & Nata_'!C47 -> 0 | K16: ='ST_FP, Maternal, Morta, & Nata_'!D47 -> 0 | L16: ='ST_FP, Maternal, Morta, & Nata_'!E47 -> 0 | M16: ='ST_FP, Maternal, Morta, & Nata_'!F47 -> 0 | N16: ='ST_FP, Maternal, Morta, & Nata_'!C66 -> 0 | O16: ='ST_FP, Maternal, Morta, & Nata_'!D66 -> 0 | P16: ='ST_FP, Maternal, Morta, & Nata_'!E66 -> 0 | Q16: ='ST_FP, Maternal, Morta, & Nata_'!F66 -> 0 | R16: ='ST_FP, Maternal, Morta, & Nata_'!C85 -> 0 | S16: ='ST_FP, Maternal, Morta, & Nata_'!D85 -> 0 | T16: ='ST_FP, Maternal, Morta, & Nata_'!E85 -> 6 | U16: ='ST_FP, Maternal, Morta, & Nata_'!F85 -> 6 | V16: ='ST_FP, Maternal, Morta, & Nata_'!C104 -> 0 | W16: ='ST_FP, Maternal, Morta, & Nata_'!D104 -> 0 | X16: ='ST_FP, Maternal, Morta, & Nata_'!E104 -> 0 | Y16: ='ST_FP, Maternal, Morta, & Nata_'!F104 -> 0
A17: 2. NSV | B17: ='ST_FP, Maternal, Morta, & Nata_'!C10 -> 0 | C17: ='ST_FP, Maternal, Morta, & Nata_'!D10 -> 0 | D17: ='ST_FP, Maternal, Morta, & Nata_'!E10 -> 0 | E17: ='ST_FP, Maternal, Morta, & Nata_'!F10 -> 0 | F17: ='ST_FP, Maternal, Morta, & Nata_'!C29 -> 0 | G17: ='ST_FP, Maternal, Morta, & Nata_'!D29 -> 0 | H17: ='ST_FP, Maternal, Morta, & Nata_'!E29 -> 0 | I17: ='ST_FP, Maternal, Morta, & Nata_'!F29 -> 0 | J17: ='ST_FP, Maternal, Morta, & Nata_'!C48 -> 0 | K17: ='ST_FP, Maternal, Morta, & Nata_'!D48 -> 0 | L17: ='ST_FP, Maternal, Morta, & Nata_'!E48 -> 0 | M17: ='ST_FP, Maternal, Morta, & Nata_'!F48 -> 0 | N17: ='ST_FP, Maternal, Morta, & Nata_'!C67 -> 0 | O17: ='ST_FP, Maternal, Morta, & Nata_'!D67 -> 0 | P17: ='ST_FP, Maternal, Morta, & Nata_'!E67 -> 0 | Q17: ='ST_FP, Maternal, Morta, & Nata_'!F67 -> 0 | R17: ='ST_FP, Maternal, Morta, & Nata_'!C86 -> 0 | S17: ='ST_FP, Maternal, Morta, & Nata_'!D86 -> 0 | T17: ='ST_FP, Maternal, Morta, & Nata_'!E86 -> 0 | U17: ='ST_FP, Maternal, Morta, & Nata_'!F86 -> 0 | V17: ='ST_FP, Maternal, Morta, & Nata_'!C105 -> 0 | W17: ='ST_FP, Maternal, Morta, & Nata_'!D105 -> 0 | X17: ='ST_FP, Maternal, Morta, & Nata_'!E105 -> 0 | Y17: ='ST_FP, Maternal, Morta, & Nata_'!F105 -> 0
A18: 3. Condom | B18: ='ST_FP, Maternal, Morta, & Nata_'!C11 -> 0 | C18: ='ST_FP, Maternal, Morta, & Nata_'!D11 -> 1 | D18: ='ST_FP, Maternal, Morta, & Nata_'!E11 -> 2 | E18: ='ST_FP, Maternal, Morta, & Nata_'!F11 -> 3 | F18: ='ST_FP, Maternal, Morta, & Nata_'!C30 -> 0 | G18: ='ST_FP, Maternal, Morta, & Nata_'!D30 -> 0 | H18: ='ST_FP, Maternal, Morta, & Nata_'!E30 -> 0 | I18: ='ST_FP, Maternal, Morta, & Nata_'!F30 -> 0 | J18: ='ST_FP, Maternal, Morta, & Nata_'!C49 -> 0 | K18: ='ST_FP, Maternal, Morta, & Nata_'!D49 -> 0 | L18: ='ST_FP, Maternal, Morta, & Nata_'!E49 -> 0 | M18: ='ST_FP, Maternal, Morta, & Nata_'!F49 -> 0 | N18: ='ST_FP, Maternal, Morta, & Nata_'!C68 -> 0 | O18: ='ST_FP, Maternal, Morta, & Nata_'!D68 -> 0 | P18: ='ST_FP, Maternal, Morta, & Nata_'!E68 -> 0 | Q18: ='ST_FP, Maternal, Morta, & Nata_'!F68 -> 0 | R18: ='ST_FP, Maternal, Morta, & Nata_'!C87 -> 0 | S18: ='ST_FP, Maternal, Morta, & Nata_'!D87 -> 1 | T18: ='ST_FP, Maternal, Morta, & Nata_'!E87 -> 2 | U18: ='ST_FP, Maternal, Morta, & Nata_'!F87 -> 3 | V18: ='ST_FP, Maternal, Morta, & Nata_'!C106 -> 0 | W18: ='ST_FP, Maternal, Morta, & Nata_'!D106 -> 0 | X18: ='ST_FP, Maternal, Morta, & Nata_'!E106 -> 0 | Y18: ='ST_FP, Maternal, Morta, & Nata_'!F106 -> 0
A19: 4. Pills | B19: ='ST_FP, Maternal, Morta, & Nata_'!C12 -> 0 | C19: ='ST_FP, Maternal, Morta, & Nata_'!D12 -> 1 | D19: ='ST_FP, Maternal, Morta, & Nata_'!E12 -> 135 | E19: ='ST_FP, Maternal, Morta, & Nata_'!F12 -> 136 | F19: ='ST_FP, Maternal, Morta, & Nata_'!C31 -> 0 | G19: ='ST_FP, Maternal, Morta, & Nata_'!D31 -> 0 | H19: ='ST_FP, Maternal, Morta, & Nata_'!E31 -> 0 | I19: ='ST_FP, Maternal, Morta, & Nata_'!F31 -> 0 | J19: ='ST_FP, Maternal, Morta, & Nata_'!C50 -> 0 | K19: ='ST_FP, Maternal, Morta, & Nata_'!D50 -> 0 | L19: ='ST_FP, Maternal, Morta, & Nata_'!E50 -> 2 | M19: ='ST_FP, Maternal, Morta, & Nata_'!F50 -> 2 | N19: ='ST_FP, Maternal, Morta, & Nata_'!C69 -> 0 | O19: ='ST_FP, Maternal, Morta, & Nata_'!D69 -> 0 | P19: ='ST_FP, Maternal, Morta, & Nata_'!E69 -> 16 | Q19: ='ST_FP, Maternal, Morta, & Nata_'!F69 -> 16 | R19: ='ST_FP, Maternal, Morta, & Nata_'!C88 -> 0 | S19: ='ST_FP, Maternal, Morta, & Nata_'!D88 -> 1 | T19: ='ST_FP, Maternal, Morta, & Nata_'!E88 -> 121 | U19: ='ST_FP, Maternal, Morta, & Nata_'!F88 -> 122 | V19: ='ST_FP, Maternal, Morta, & Nata_'!C107 -> 0 | W19: ='ST_FP, Maternal, Morta, & Nata_'!D107 -> 0 | X19: ='ST_FP, Maternal, Morta, & Nata_'!E107 -> 0 | Y19: ='ST_FP, Maternal, Morta, & Nata_'!F107 -> 0
A20: a. Pills-POP | B20: ='ST_FP, Maternal, Morta, & Nata_'!C13 -> 0 | C20: ='ST_FP, Maternal, Morta, & Nata_'!D13 -> 0 | D20: ='ST_FP, Maternal, Morta, & Nata_'!E13 -> 3 | E20: ='ST_FP, Maternal, Morta, & Nata_'!F13 -> 3 | F20: ='ST_FP, Maternal, Morta, & Nata_'!C32 -> 0 | G20: ='ST_FP, Maternal, Morta, & Nata_'!D32 -> 0 | H20: ='ST_FP, Maternal, Morta, & Nata_'!E32 -> 0 | I20: ='ST_FP, Maternal, Morta, & Nata_'!F32 -> 0 | J20: ='ST_FP, Maternal, Morta, & Nata_'!C51 -> 0 | K20: ='ST_FP, Maternal, Morta, & Nata_'!D51 -> 0 | L20: ='ST_FP, Maternal, Morta, & Nata_'!E51 -> 2 | M20: ='ST_FP, Maternal, Morta, & Nata_'!F51 -> 2 | N20: ='ST_FP, Maternal, Morta, & Nata_'!C70 -> 0 | O20: ='ST_FP, Maternal, Morta, & Nata_'!D70 -> 0 | P20: ='ST_FP, Maternal, Morta, & Nata_'!E70 -> 0 | Q20: ='ST_FP, Maternal, Morta, & Nata_'!F70 -> 0 | R20: ='ST_FP, Maternal, Morta, & Nata_'!C89 -> 0 | S20: ='ST_FP, Maternal, Morta, & Nata_'!D89 -> 0 | T20: ='ST_FP, Maternal, Morta, & Nata_'!E89 -> 5 | U20: ='ST_FP, Maternal, Morta, & Nata_'!F89 -> 5 | V20: ='ST_FP, Maternal, Morta, & Nata_'!C108 -> 0 | W20: ='ST_FP, Maternal, Morta, & Nata_'!D108 -> 0 | X20: ='ST_FP, Maternal, Morta, & Nata_'!E108 -> 0 | Y20: ='ST_FP, Maternal, Morta, & Nata_'!F108 -> 0
A21: b. Pills-COC | B21: ='ST_FP, Maternal, Morta, & Nata_'!C14 -> 0 | C21: ='ST_FP, Maternal, Morta, & Nata_'!D14 -> 1 | D21: ='ST_FP, Maternal, Morta, & Nata_'!E14 -> 132 | E21: ='ST_FP, Maternal, Morta, & Nata_'!F14 -> 133 | F21: ='ST_FP, Maternal, Morta, & Nata_'!C33 -> 0 | G21: ='ST_FP, Maternal, Morta, & Nata_'!D33 -> 0 | H21: ='ST_FP, Maternal, Morta, & Nata_'!E33 -> 0 | I21: ='ST_FP, Maternal, Morta, & Nata_'!F33 -> 0 | J21: ='ST_FP, Maternal, Morta, & Nata_'!C52 -> 0 | K21: ='ST_FP, Maternal, Morta, & Nata_'!D52 -> 0 | L21: ='ST_FP, Maternal, Morta, & Nata_'!E52 -> 0 | M21: ='ST_FP, Maternal, Morta, & Nata_'!F52 -> 0 | N21: ='ST_FP, Maternal, Morta, & Nata_'!C71 -> 0 | O21: ='ST_FP, Maternal, Morta, & Nata_'!D71 -> 0 | P21: ='ST_FP, Maternal, Morta, & Nata_'!E71 -> 16 | Q21: ='ST_FP, Maternal, Morta, & Nata_'!F71 -> 16 | R21: ='ST_FP, Maternal, Morta, & Nata_'!C90 -> 0 | S21: ='ST_FP, Maternal, Morta, & Nata_'!D90 -> 1 | T21: ='ST_FP, Maternal, Morta, & Nata_'!E90 -> 116 | U21: ='ST_FP, Maternal, Morta, & Nata_'!F90 -> 117 | V21: ='ST_FP, Maternal, Morta, & Nata_'!C109 -> 0 | W21: ='ST_FP, Maternal, Morta, & Nata_'!D109 -> 0 | X21: ='ST_FP, Maternal, Morta, & Nata_'!E109 -> 0 | Y21: ='ST_FP, Maternal, Morta, & Nata_'!F109 -> 0
A22: 5. Injectables (DMPA/POI) | B22: ='ST_FP, Maternal, Morta, & Nata_'!C15 -> 0 | C22: ='ST_FP, Maternal, Morta, & Nata_'!D15 -> 2 | D22: ='ST_FP, Maternal, Morta, & Nata_'!E15 -> 29 | E22: ='ST_FP, Maternal, Morta, & Nata_'!F15 -> 31 | F22: ='ST_FP, Maternal, Morta, & Nata_'!C34 -> 0 | G22: ='ST_FP, Maternal, Morta, & Nata_'!D34 -> 0 | H22: ='ST_FP, Maternal, Morta, & Nata_'!E34 -> 0 | I22: ='ST_FP, Maternal, Morta, & Nata_'!F34 -> 0 | J22: ='ST_FP, Maternal, Morta, & Nata_'!C53 -> 0 | K22: ='ST_FP, Maternal, Morta, & Nata_'!D53 -> 0 | L22: ='ST_FP, Maternal, Morta, & Nata_'!E53 -> 3 | M22: ='ST_FP, Maternal, Morta, & Nata_'!F53 -> 3 | N22: ='ST_FP, Maternal, Morta, & Nata_'!C72 -> 0 | O22: ='ST_FP, Maternal, Morta, & Nata_'!D72 -> 0 | P22: ='ST_FP, Maternal, Morta, & Nata_'!E72 -> 0 | Q22: ='ST_FP, Maternal, Morta, & Nata_'!F72 -> 0 | R22: ='ST_FP, Maternal, Morta, & Nata_'!C91 -> 0 | S22: ='ST_FP, Maternal, Morta, & Nata_'!D91 -> 2 | T22: ='ST_FP, Maternal, Morta, & Nata_'!E91 -> 32 | U22: ='ST_FP, Maternal, Morta, & Nata_'!F91 -> 34 | V22: ='ST_FP, Maternal, Morta, & Nata_'!C110 -> 0 | W22: ='ST_FP, Maternal, Morta, & Nata_'!D110 -> 0 | X22: ='ST_FP, Maternal, Morta, & Nata_'!E110 -> 0 | Y22: ='ST_FP, Maternal, Morta, & Nata_'!F110 -> 0
